Workbook

Sheet map_appelations
A1: denom
A2: Côtes du Rhône
A3: Bordeaux | B3: Bordeaux supérieur | C3: Crémant de Bordeaux | D3: Saint-Emilion | E3: Saint-Emilion grand cru
A4: Bordeaux | B4: Bordeaux supérieur | C4: Crémant de Bordeaux | D4: Montagne-Saint-Emilion
A5: Bergerac | B5: Côtes de Bergerac | C5: Monbazillac
A6: Bordeaux | B6: Bordeaux supérieur | C6: Crémant de Bordeaux
A7: Bordeaux | B7: Bordeaux supérieur | C7: Crémant de Bordeaux | D7: Lussac-Saint-Emilion
A8: Bordeaux | B8: Bordeaux supérieur | C8: Crémant de Bordeaux | D8: Haut-Médoc | E8: Médoc | F8: Saint-Estèphe
A9: Bergerac | B9: Côtes de Bergerac | C9: Monbazillac
A10: Buzet
A11: Bergerac | B11: Côtes de Bergerac
A12: Côtes du Rhône
A13: Bordeaux | B13: Bordeaux supérieur | C13: Crémant de Bordeaux | D13: Entre-deux-Mers
A14: Bordeaux | B14: Bordeaux supérieur | C14: Crémant de Bordeaux | D14: Médoc
A15: Bordeaux | B15: Bordeaux supérieur | C15: Crémant de Bordeaux | D15: Entre-deux-Mers
A16: Côtes du Rhône
A17: Côtes du Roussillon | B17: Côtes du Roussillon Villages | C17: Languedoc
A18: Bordeaux | B18: Bordeaux supérieur | C18: Crémant de Bordeaux | D18: Entre-deux-Mers
A19: Grand Roussillon | B19: Muscat de Rivesaltes | C19: Rivesaltes
A20: Buzet
A21: Bordeaux | B21: Bordeaux supérieur | C21: Crémant de Bordeaux | D21: Haut-Médoc | E21: Médoc | F21: Saint-Julien
A22: Bordeaux | B22: Bordeaux supérieur | C22: Crémant de Bordeaux | D22: Saint-Emilion | E22: Saint-Emilion grand cru
A23: Bordeaux | B23: Bordeaux supérieur | C23: Crémant de Bordeaux | D23: Haut-Médoc | E23: Médoc
A24: Bordeaux | B24: Bordeaux Haut-Benauge | C24: Bordeaux supérieur | D24: Crémant de Bordeaux | E24: Entre-deux-Mers | F24: Entre-deux-Mers Haut-Benauge
A25: Bordeaux | B25: Bordeaux supérieur | C25: Crémant de Bordeaux | D25: Entre-deux-Mers
A26: Bordeaux | B26: Bordeaux supérieur | C26: Crémant de Bordeaux
A27: Bordeaux | B27: Bordeaux supérieur | C27: Crémant de Bordeaux | D27: Entre-deux-Mers
A28: Bordeaux | B28: Bordeaux supérieur | C28: Crémant de Bordeaux | D28: Graves | E28: Graves supérieures
A29: Bordeaux | B29: Bordeaux supérieur | C29: Crémant de Bordeaux | D29: Haut-Médoc | E29: Médoc
A30: Bordeaux | B30: Bordeaux Haut-Benauge | C30: Bordeaux supérieur | D30: Crémant de Bordeaux | E30: Entre-deux-Mers | F30: Entre-deux-Mers Haut-Benauge
A31: Bordeaux | B31: Bordeaux supérieur | C31: Crémant de Bordeaux
A32: Buzet
A33: Bordeaux | B33: Bordeaux supérieur | C33: Crémant de Bordeaux | D33: Entre-deux-Mers
A34: Bordeaux | B34: Bordeaux supérieur | C34: Crémant de Bordeaux | D34: Côtes de Bourg | E34: Bourg et Bourgeais
A35: Bordeaux | B35: Bordeaux supérieur | C35: Crémant de Bordeaux | D35: Haut-Médoc | E35: Médoc
A36: Bordeaux | B36: Bordeaux supérieur | C36: Crémant de Bordeaux
A37: Bergerac | B37: Côtes de Bergerac
A38: Buzet
A39: Bordeaux | B39: Bordeaux supérieur | C39: Crémant de Bordeaux
A40: Bordeaux | B40: Bordeaux Haut-Benauge | C40: Bordeaux supérieur | D40: Crémant de Bordeaux | E40: Entre-deux-Mers | F40: Entre-deux-Mers Haut-Benauge
...

Sheet Feuil1
A1: {=_xlfn.UNIQUE(map_appelations!$A$2:$A$5001)} -> Côtes du Rhône
A2: Bordeaux
A3: Bergerac
A4: Buzet
A5: Côtes du Roussillon
A6: Grand Roussillon
A7: Coteaux d'Aix-en-Provence
A8: Côtes de Duras
A9: Barsac
A10: Ajaccio
A11: Côtes du Marmandais
A12: Bandol
A13: Ventoux
... A90: Estaing
A91: {=_xlfn.UNIQUE(map_appelations!$B$2:$B$5001)} -> 0
A92: Bordeaux supérieur
A93: Côtes de Bergerac
A94: Côtes du Roussillon Villages
A95: Muscat de Rivesaltes
A96: Bordeaux Haut-Benauge
A97: Bordeaux
A98: Vin de Corse ou Corse
A99: Côtes du Rhône Villages
A100: Languedoc
A101: Alsace suivi d'un nom de lieu-dit
A102: Patrimonio
A103: Grand Roussillon
... A184: Tavel
A185: {=_xlfn.UNIQUE(map_appelations!$C$2:$C$5001)} -> 0
A186: Crémant de Bordeaux
A187: Monbazillac
A188: Languedoc
A189: Rivesaltes
A190: Bordeaux supérieur
A191: Cadillac
A192: Côtes du Rhône Villages Saint-Maurice
A193: Côtes du Roussillon Villages Caramany
A194: Rosette
A195: Crémant d’Alsace
A196: Saussignac
...

Sheet Feuil2
A1: {=_xlfn.UNIQUE(Feuil1!A:A)} -> Côtes du Rhône
A2: Bordeaux
A3: Bergerac
A4: Buzet
A5: Côtes du Roussillon
A6: Grand Roussillon
A7: Coteaux d'Aix-en-Provence
A8: Côtes de Duras
A9: Barsac
A10: Ajaccio
A11: Côtes du Marmandais
A12: Bandol
A13: Ventoux
... A90: Estaing
A91: 0
A92: Bordeaux supérieur
A93: Côtes de Bergerac
A94: Côtes du Roussillon Villages
A95: Muscat de Rivesaltes
A96: Bordeaux Haut-Benauge
A97: Alsace suivi d'un nom de lieu-dit
A98: Vin de Corse ou Corse Figari
A99: Coteaux de Die
A100: Les Baux de Provence
A101: Clairette du Languedoc Cabrières
A102: Limoux
A103: Minervois
... A296: Vougeot premier cru
A297: 0

Sheet Appelations
A1: map_Appelations | B1: cave_Appelations | C1: Automatisation #1 | D1: Manuel | G1: A ajouter base cave
A2: 0 | B2: =IF(C2="",D2,C2) -> 0 | C2: =IF(COUNTIF(cave_Appelations!$A:$A,$A2)>0,$A2,"") | G2: Cairanne
A3: 0 | B3: =IF(C3="",D3,C3) -> 0 | C3: =IF(COUNTIF(cave_Appelations!$A:$A,$A3)>0,$A3,"") | G3: Hautes Cotes de Beaune
A4: Bourg et Bourgeais | B4: =IF(C4="",D4,C4) -> Côtes de Bourg, Bourg et Bourgeais | D4: Côtes de Bourg, Bourg et Bourgeais | G4: La Clape
A5: Ajaccio | B5: =IF(C5="",D5,C5) -> Ajaccio | C5: =IF(COUNTIF(cave_Appelations!$A:$A,$A5)>0,$A5,"") -> Ajaccio | G5: Bordeaux Haut-Benauge
A6: Alsace | B6: =IF(C6="",D6,C6) -> Alsace | C6: =IF(COUNTIF(cave_Appelations!$A:$A,$A6)>0,$A6,"") -> Alsace | G6: Pic Saint-Loup
A7: Alsace grand cru Mambourg | B7: =IF(C7="",D7,C7) -> Alsace grand cru | C7: =IF(COUNTIF(cave_Appelations!$A:$A,$A7)>0,$A7,"") | D7: Alsace grand cru
A8: Alsace grand cru Schlossberg | B8: =IF(C8="",D8,C8) -> Alsace grand cru | C8: =IF(COUNTIF(cave_Appelations!$A:$A,$A8)>0,$A8,"") | D8: Alsace grand cru
A9: Alsace suivi d'un nom de lieu-dit | B9: =IF(C9="",D9,C9) -> Alsace | C9: =IF(COUNTIF(cave_Appelations!$A:$A,$A9)>0,$A9,"") | D9: Alsace
A10: Anjou | B10: =IF(C10="",D10,C10) -> Anjou | C10: =IF(COUNTIF(cave_Appelations!$A:$A,$A10)>0,$A10,"") -> Anjou
A11: Anjou Villages | B11: =IF(C11="",D11,C11) -> Anjou Villages | C11: =IF(COUNTIF(cave_Appelations!$A:$A,$A11)>0,$A11,"") -> Anjou Villages
A12: Arbois | B12: =IF(C12="",D12,C12) -> Arbois | C12: =IF(COUNTIF(cave_Appelations!$A:$A,$A12)>0,$A12,"") -> Arbois
A13: Arbois Pupillin | B13: =IF(C13="",D13,C13) -> Arbois | C13: =IF(COUNTIF(cave_Appelations!$A:$A,$A13)>0,$A13,"") | D13: Arbois
A14: Bandol | B14: =IF(C14="",D14,C14) -> Bandol | C14: =IF(COUNTIF(cave_Appelations!$A:$A,$A14)>0,$A14,"") -> Bandol
A15: Banyuls | B15: =IF(C15="",D15,C15) -> Banyuls | C15: =IF(COUNTIF(cave_Appelations!$A:$A,$A15)>0,$A15,"") -> Banyuls
A16: Banyuls grand cru | B16: =IF(C16="",D16,C16) -> Banyuls grand cru | C16: =IF(COUNTIF(cave_Appelations!$A:$A,$A16)>0,$A16,"") -> Banyuls grand cru
A17: Barsac | B17: =IF(C17="",D17,C17) -> Barsac | C17: =IF(COUNTIF(cave_Appelations!$A:$A,$A17)>0,$A17,"") -> Barsac
A18: Béarn | B18: =IF(C18="",D18,C18) -> Béarn | C18: =IF(COUNTIF(cave_Appelations!$A:$A,$A18)>0,$A18,"") -> Béarn
A19: Beaujolais | B19: =IF(C19="",D19,C19) -> Beaujolais | C19: =IF(COUNTIF(cave_Appelations!$A:$A,$A19)>0,$A19,"") -> Beaujolais
A20: Beaujolais Beaujeu | B20: =IF(C20="",D20,C20) -> Beaujolais-Villages | C20: =IF(COUNTIF(cave_Appelations!$A:$A,$A20)>0,$A20,"") | D20: Beaujolais-Villages
A21: Beaujolais La Chapelle-de-Guinchay | B21: =IF(C21="",D21,C21) -> Beaujolais-Villages | C21: =IF(COUNTIF(cave_Appelations!$A:$A,$A21)>0,$A21,"") | D21: Beaujolais-Villages
A22: Beaujolais Lantignié | B22: =IF(C22="",D22,C22) -> Beaujolais-Villages | C22: =IF(COUNTIF(cave_Appelations!$A:$A,$A22)>0,$A22,"") | D22: Beaujolais-Villages
A23: Beaujolais Le Perréon | B23: =IF(C23="",D23,C23) -> Beaujolais-Villages | C23: =IF(COUNTIF(cave_Appelations!$A:$A,$A23)>0,$A23,"") | D23: Beaujolais-Villages
A24: Beaujolais Odenas | B24: =IF(C24="",D24,C24) -> Beaujolais-Villages | C24: =IF(COUNTIF(cave_Appelations!$A:$A,$A24)>0,$A24,"") | D24: Beaujolais-Villages
A25: Beaujolais Quincié-en-Beaujolais | B25: =IF(C25="",D25,C25) -> Beaujolais-Villages | C25: =IF(COUNTIF(cave_Appelations!$A:$A,$A25)>0,$A25,"") | D25: Beaujolais-Villages
A26: Beaujolais Saint-Etienne-des-Oullières | B26: =IF(C26="",D26,C26) -> Beaujolais-Villages | C26: =IF(COUNTIF(cave_Appelations!$A:$A,$A26)>0,$A26,"") | D26: Beaujolais-Villages
A27: Beaujolais Saint-Lager | B27: =IF(C27="",D27,C27) -> Beaujolais-Villages | C27: =IF(COUNTIF(cave_Appelations!$A:$A,$A27)>0,$A27,"") | D27: Beaujolais-Villages
A28: Beaujolais Vaux-en-Beaujolais | B28: =IF(C28="",D28,C28) -> Beaujolais-Villages | C28: =IF(COUNTIF(cave_Appelations!$A:$A,$A28)>0,$A28,"") | D28: Beaujolais-Villages
A29: Beaujolais Villages | B29: =IF(C29="",D29,C29) -> Beaujolais-Villages | C29: =IF(COUNTIF(cave_Appelations!$A:$A,$A29)>0,$A29,"") | D29: Beaujolais-Villages
A30: Beaumes de Venise | B30: =IF(C30="",D30,C30) -> Beaumes de Venise | C30: =IF(COUNTIF(cave_Appelations!$A:$A,$A30)>0,$A30,"") -> Beaumes de Venise
A31: Bergerac | B31: =IF(C31="",D31,C31) -> Bergerac | C31: =IF(COUNTIF(cave_Appelations!$A:$A,$A31)>0,$A31,"") -> Bergerac
A32: Blaye | B32: =IF(C32="",D32,C32) -> Blaye | C32: =IF(COUNTIF(cave_Appelations!$A:$A,$A32)>0,$A32,"") -> Blaye
A33: Bordeaux | B33: =IF(C33="",D33,C33) -> Bordeaux | C33: =IF(COUNTIF(cave_Appelations!$A:$A,$A33)>0,$A33,"") -> Bordeaux
A34: Bordeaux Haut-Benauge | B34: =IF(C34="",D34,C34) -> Bordeaux | C34: =IF(COUNTIF(cave_Appelations!$A:$A,$A34)>0,$A34,"") | D34: Bordeaux
A35: Bordeaux supérieur | B35: =IF(C35="",D35,C35) -> Bordeaux supérieur | C35: =IF(COUNTIF(cave_Appelations!$A:$A,$A35)>0,$A35,"") -> Bordeaux supérieur
A36: Bourgogne | B36: =IF(C36="",D36,C36) -> Bourgogne | C36: =IF(COUNTIF(cave_Appelations!$A:$A,$A36)>0,$A36,"") -> Bourgogne
A37: Bourgogne aligoté | B37: =IF(C37="",D37,C37) -> Bourgogne aligoté | C37: =IF(COUNTIF(cave_Appelations!$A:$A,$A37)>0,$A37,"") -> Bourgogne aligoté
A38: Bourgogne Chitry | B38: =IF(C38="",D38,C38) -> Bourgogne | C38: =IF(COUNTIF(cave_Appelations!$A:$A,$A38)>0,$A38,"") | D38: Bourgogne
A39: Bourgogne Côte Chalonnaise | B39: =IF(C39="",D39,C39) -> Bourgogne | C39: =IF(COUNTIF(cave_Appelations!$A:$A,$A39)>0,$A39,"") | D39: Bourgogne
A40: Bourgogne Côte d'Or | B40: =IF(C40="",D40,C40) -> Bourgogne | C40: =IF(COUNTIF(cave_Appelations!$A:$A,$A40)>0,$A40,"") | D40: Bourgogne
...

Sheet cave_Appelations
A1: Appelation | B1: Région | C1: ID_Appelation
A2: Afrique du Sud | B2: Etranger | C2: AFRIQUE DU SUD
A3: Ajaccio | B3: Provence | C3: AJACCIO
A4: Allemagne | B4: Etranger | C4: ALLEMAGNE
A5: Aloxe-Corton | B5: Bourgogne | C5: ALOXE CORTON
A6: Aloxe-Corton 1er Cru | B6: Bourgogne | C6: ALOXE CORTON 1ER CRU
A7: Alsace | B7: Alsace | C7: ALSACE
A8: Alsace grand cru | B8: Alsace | C8: ALSACE GRAND CRU
A9: Angleterre | B9: Etranger | C9: ANGLETERRE
A10: Anjou | B10: Loire | C10: ANJOU
A11: Anjou Villages | B11: Loire | C11: ANJOU VILLAGES
A12: Anjou Villages Brissac | B12: Loire | C12: ANJOU VILLAGES BRISSAC
... A360: Vouvray | B360: Loire | C360: VOUVRAY

Sheet Map2_AOC
A1: AOC data | B1: Base Cave Clean
A2: Ajaccio | B2: Ajaccio
A3: Aloxe-Corton | B3: Aloxe-Corton
A4: Aloxe-Corton premier cru | B4: Aloxe-Corton 1er Cru
A5: Aloxe-Corton premier cru Clos des Maréchaudes | B5: Aloxe-Corton 1er Cru
A6: Aloxe-Corton premier cru Clos du Chapitre | B6: Aloxe-Corton 1er Cru
A7: Aloxe-Corton premier cru La Coutière | B7: Aloxe-Corton 1er Cru
A8: Aloxe-Corton premier cru La Maréchaude | B8: Aloxe-Corton 1er Cru
A9: Aloxe-Corton premier cru La Toppe au Vert | B9: Aloxe-Corton 1er Cru
A10: Aloxe-Corton premier cru Les Chaillots | B10: Aloxe-Corton 1er Cru
A11: Aloxe-Corton premier cru Les Fournières | B11: Aloxe-Corton 1er Cru
A12: Aloxe-Corton premier cru Les Guérets | B12: Aloxe-Corton 1er Cru
... A1335: Whisky breton ou Whisky de Bretagne | B1335: Whisky breton ou Whisky de Bretagne
